Workbook

Sheet 总览
A1: 2026 年 12 月 CET-6 425+ 备考计划
A2: 初版 v1.0｜按 450 能力构建容错｜莆田学院｜生成于 2026-08-27
A4: 一眼看懂：当前差距与目标
A5: 模块 | B5: 当前分 | C5: 训练目标 | D5: 需提升 | E5: 策略 | F5: 优先级
A6: 听力 | B6: 78 | C6: 150 | D6: =C6-B6 | E6: 真题原音；讲座/讲话和错句精听优先 | F6: 核心
A7: 阅读 | B7: 86 | C7: 165 | D7: =C7-B7 | E7: 仔细阅读 + 长篇匹配优先；选词填空低投入 | F7: 核心
A8: 写作+翻译 | B8: 117 | C8: 135 | D8: =C8-B8 | E8: 每周 1 篇完整输出 + 改写；维持优势 | F8: 维持提分
A9: 总分 | B9: 281 | C9: 450 | D9: =C9-B9 | E9: 以两次连续 425+、至少一次 450 左右为考前信号 | F9: 目标
A11: 考试与校历状态
A12: 事项 | B12: 日期 | C12: 状态 | D12: 计划处理
A13: 正式开练 | B13: 46272 | C13: 已确认 | D13: 校历 9/7 开学
A14: 中秋节 | B14: 46290 | C14: 已确认 | D14: 9/25 轻量；国务院假期 9/25–27
A15: 新加坡旅行 | B15: 2026-09-30 至 2026-10-05 | C15: 用户确认 | D15: 9/30–10/1 仅词汇；10/2–10/5 完全留空
A16: 运动会 | B16: 2026-11-12 至 2026-11-14 | C16: 校历可明确识别 | D16: 三天只留词汇维护；不补课
A17: CET-6 笔试 | B17: 46368 | C17: 待官方确认 | D17: 仅作倒排占位；暂按 15:00–17:25 预留
A19: 阶段路线
A20: 阶段 | B20: 日期 | C20: 主目标 | D20: 听力 | E20: 阅读 | F20: 写译
A21: 诊断期 | B21: 9/7–9/13 | C21: 完成 F0 基线并分类错因 | D21: 找主要失分点 | E21: 找主要失分点 | F21: 完成两项限时样本
A22: 基础期 | B22: 9/14–10/11 | C22: 把做题流程固定下来 | D22: 长对话/篇章/讲座逐类 | E22: 证据定位与同义替换 | F22: 每周 1 次完整输出
A23: 强化期 | B23: 10/12–11/1 | C23: 整模块计时 + 首次全真 | D23: 14–15/25 | E23: 18–19/30 | F23: 30 分钟内完成
A24: 模考期 | B24: 11/2–11/29 | C24: M02–M05 每周一套 | D24: 向 16–17/25 靠拢 | E24: 向 20–21/30 靠拢 | F24: 改写而非抄范文
A25: 冲刺期 | B25: 11/30–12/11 | C25: M06 + 错题封口 + 减量 | D25: 保持原速手感 | E25: 稳定时间分配 | F25: 只复习个人骨架
A27: 执行数据（随每日计划更新） | H27: 三条执行规则
A28: 指标 | B28: 当前值 | C28: 单位 | H28: 1. 未完成不整体顺延：只把当天最重要的一项放到周日，最多带 1 项欠账。
A29: 计划学习天数 | B29: =COUNTIF('每日计划'!$F:$F,">0") | C29: 天 | H29: 2. 最低可执行版（忙到爆时）：10 分钟到期词 + 15 分钟错句盲听 + 15 分钟仔细阅读证据定位，共 40 分钟。
A30: 已完成天数 | B30: =COUNTIF('每日计划'!$N:$N,"已完成") | C30: 天 | H30: 3. 真题顺序：F0/D01–D05 可拆；M01–M06 必须保留到指定模考日，提前不看答案。
A31: 总体完成率 | B31: =IFERROR(B30/B29,0) | C31: % | H31: 4. 估分只能看趋势：CET 采用常模转换，原始正确数不能简单线性换算成 710 分制。
A32: 计划总时长 | B32: =SUM('每日计划'!$F:$F)/60 | C32: 小时 | H32: 5. 若正式考试晚于 12/12：将 12/12 改为轻量全真/复测，并重复最后冲刺周；若提前，则从考前 6 天直接执行第 14 周。
A33: 实际总时长 | B33: =SUM('每日计划'!$O:$O)/60 | C33: 小时
A34: 最近模考估分 | B34: =IFERROR(LOOKUP(2,1/('模考记录'!$H:$H<>""),'模考记录'!$H:$H),"待填写") | C34: 分
A36: 官方状态说明（务必保留）
A37: 截至 2026-08-27，教育部教育考试院 CET 考试动态与报名网仍未发布 2026 年下半年正式报名/考试公告。本计划以 2026-12-12 为倒排占位日；上海市年度考试计划曾列该日，但它不是本次中央正式公告，且年度计划可能调整。CET-6 暂按近次官方时段 15:00–17:25 预留，最终以教育部教育考试院公告、莆田学院通知和准考证为准。

Sheet 每日计划
A1: 日期 | B1: 周次 | C1: 星期 | D1: 阶段 | E1: 日型 | F1: 计划(min) | G1: 单词 | H1: 听力 | I1: 阅读 | J1: 写作/翻译 | K1: 复盘/输出 | L1: 资料/编号 | M1: 当日完成标准 | N1: 状态 | O1: 实际(min) | P1: 自评(1-5) | Q1: 备注
A2: 46272 | B2: 1 | C2: 周一 | D2: 诊断期 | E2: 工作日 | F2: 105 | G2: [25min] 安装/选定不背单词，选择六级词书；做 10 分钟词汇熟悉度抽测后开始新词 30 | H2: [20min] 阅读 CET-6 听力题型与答题顺序；试听随书音频，确认设备 | I2: [20min] 阅读题型与时间分配：选词 8 分钟、匹配 12 分钟、仔细阅读 20 分钟 | J2: [20min] 看 1 道作文和 1 道翻译要求，只做审题不看范文 | K2: [20min] 建立真题编号 F0/D01–D05/M01–M06；填写总览基础分 | L2: 本工作簿；真题册说明页；不背单词 | M2: 所有工具可用；12 套真题已编号；未提前看保留模考卷答案 | N2: 未开始
A3: 46273 | B3: 1 | C3: 周二 | D3: 诊断期 | E3: 工作日 | F3: 110 | G3: [25min] 新词 35 + 到期复习 | H3: [45min] 用真题册例题做 1 组听力：限时→标错因→精听 6 个难句 | I3: [20min] 把听力错因分为听不出、词不懂、定位错、走神 | K3: [20min] 记录耳机/音量、最易走神的时段和应对动作 | L3: 真题册例题（非 F0）；随书音频 | M3: 至少找到 2 个主要听力问题；6 个难句可原速跟读 | N3: 未开始
A4: 46274 | B4: 1 | C4: 周三 | D4: 诊断期 | E4: 工作日 | F4: 110 | G4: [25min] 新词 35 + 到期复习 | I4: [60min] 用真题册例题做：匹配 1 篇 + 仔细阅读 1 篇；逐题圈定位句和同义替换 | K4: [25min] 把阅读错因分为词汇、定位、长难句、逻辑、超时 | L4: 真题册例题（非 F0） | M4: 完成阅读时间记录；每道错题都能归入一个错因 | N4: 未开始
A5: 46275 | B5: 1 | C5: 周四 | D5: 诊断期 | E5: 工作日 | F5: 110 | G5: [25min] 新词 35 + 到期复习 | J5: [60min] 作文 30 分钟 + 翻译 30 分钟，均独立完成后再看范文 | K5: [25min] 各挑 3 个问题：审题/结构/语法/搭配；不抄整篇范文 | L5: 真题册例题；计时器 | M5: 两项都在时限内完成；得到各 3 个可执行改进点 | N5: 未开始
A6: 46276 | B6: 1 | C6: 周五 | D6: 诊断期 | E6: 工作日 | F6: 95 | G6: [20min] 只做本周到期复习 | H6: [20min] 重听 9/8 的 6 个难句，不看文本复述 | I6: [20min] 重做 9/9 的错题，不看答案 | J6: [15min] 整理明天 F0 模考的作文/翻译时间节点 | K6: [20min] 写下基线预测与三条模考纪律；今晚减量 | L6: 本周错题；F0（不得翻阅） | M6: 设备就绪；错题二测完成；今晚不加练 | N6: 未开始
A7: 46277 | B7: 1 | C7: 周六 | D7: 诊断期 | E7: 全真模考 | F7: 170 | G7: [15min] 只复习到期词，不开新词 | K7: [155min] F0 全真 130 分钟：写作→听力→阅读→翻译，不暂停不查词；25 分钟核对并录入成绩 | L7: F0（保留卷）；计时器；模考记录 | M7: 严格完成 130 分钟；出版社估分目标 记录基线；分数只看趋势，不做简单线性换算 | N7: 未开始
A8: 46278 | B8: 1 | C8: 周日 | D8: 诊断期 | E8: 模考复盘 | F8: 170 | G8: [20min] 模考错词 + 到期词，不开新词 | H8: [45min] F0 听力错段：先盲听，再看文本听写 8 句，最后原速复测 | I8: [45min] F0 阅读错题：重做、标定位句、写干扰项陷阱 | J8: [40min] F0 作文/翻译：各选最差 1 段改写；只保留 3 个可复用句型 | K8: [20min] 填写每周复盘和错题记录；下周只修最大 2 个问题 | L8: F0；错题记录；每周复盘 | M8: 四部分都有复盘产物；48 小时复测日期已写入错题表 | N8: 未开始
A9: 46279 | B9: 2 | C9: 周一 | D9: 基础期 | E9: 工作日 | F9: 105 | G9: [25min] 不背单词·六级词书：新词 40（周末 50）+ 到期复习；20–25 分钟到点即停 | H9: [40min] D01 长对话 1 组：限时作答→精听 2 轮→听写 6 个转折/问题句 | I9: [30min] D01 仔细阅读 1 篇：10 分钟做题 + 20 分钟逐题定位证据 | K9: [10min] 错题写 1 条根因 + 1 条下次动作 | L9: D01；不背单词；每日英语听力/随书音频 | M9: 能指出每道错题的原文证据；精听句可脱稿复述大意 | N9: 未开始
A10: 46280 | B10: 2 | C10: 周二 | D10: 基础期 | E10: 工作日 | F10: 110 | G10: [25min] 不背单词·六级词书：新词 40（周末 50）+ 到期复习；20–25 分钟到点即停 | H10: [30min] D01 篇章听力 1 组：先盲听作答，再逐句回放难句 | I10: [35min] D01 长篇匹配：15 分钟限时 + 20 分钟整理同义替换 | J10: [20min] 真题翻译 3–4 句：先独立写，再对照范文只改语法和搭配 | L10: D01；真题范文 | M10: 记录至少 5 组同义替换；翻译改出 3 处可复用表达 | N10: 未开始
A11: 46281 | B11: 2 | C11: 周三 | D11: 基础期 | E11: 工作日 | F11: 110 | G11: [25min] 不背单词·六级词书：新词 40（周末 50）+ 到期复习；20–25 分钟到点即停 | H11: [45min] D01 讲座/讲话 1 组：画结构（主题→分点→例子）并跟读 8 句 | I11: [30min] D01 仔细阅读 1 篇：训练长对话 + 仔细阅读，每题标定位词 | J11: [10min] 写作：只列 3 段提纲 + 每段 1 个主题句 | L11: D01；随书听力文本 | M11: 能用中文复述讲座三层结构；提纲 10 分钟内完成 | N11: 未开始
A12: 46282 | B12: 2 | C12: 周四 | D12: 基础期 | E12: 工作日 | F12: 115 | G12: [25min] 不背单词·六级词书：新词 40（周末 50）+ 到期复习；20–25 分钟到点即停 | H12: [35min] D01 讲座/讲话第 2 组：限时 + 错句精听 + 隔句跟读 | I12: [40min] D01 仔细阅读第 2 篇：12 分钟做题 + 28 分钟错项排除 | J12: [15min] 翻译：复写本周 5 个高频句型，换主题词各造 1 句 | L12: D01；错题记录 | M12: 讲座错题二次作答全对；阅读能解释 4 个干扰项为何错 | N12: 未开始
A13: 46283 | B13: 2 | C13: 周五 | D13: 基础期 | E13: 工作日 | F13: 100 | G13: [20min] 本周词汇到期复习，不加量 | H13: [25min] 本周精听句盲听复测：不看文本写关键词，错句回放 1 次 | I13: [30min] D01 选词填空 1 篇：12 分钟限时；只总结词性和固定搭配 | J13: [20min] 写作：把周三提纲扩写为开头 + 结尾，各 3–4 句 | K13: [5min] 标记周末优先复习的 3 个错误 | L13: D01；本周错题 | M13: 精听复测正确率≥80%；形成 1 个可复用开头和结尾 | N13: 未开始
A14: 46284 | B14: 2 | C14: 周六 | D14: 基础期 | E14: 周末 | F14: 165 | G14: [25min] 新词 50 + 到期复习 | H14: [55min] D01 听力 25 题整套限时 30 分钟 + 25 分钟归因 | I14: [50min] D01 阅读：长篇匹配 1 篇 + 仔细阅读 1 篇，均计时 | J14: [20min] 写作：完成 1 个 30 分钟题目的审题、提纲和首段 | K14: [15min] 将本日错题录入错题记录，安排 48 小时复测 | L14: D01；计时器；错题记录 | M14: 听力全程不停；阅读总用时≤40 分钟；错题全部有根因标签 | N14: 未开始
A15: 46285 | B15: 2 | C15: 周日 | D15: 基础期 | E15: 调休上课日 | F15: 110 | G15: [20min] 到期词复习；按工作日强度，不加新词 | H15: [35min] D01 本周错句盲听 + 跟读；只修最常见错因 | I15: [30min] D01 仔细阅读错题二测，重新标证据 | J15: [15min] 完整翻译只改写最差 3 句 | K15: [10min] 简版周复盘：下周唯一重点 | L15: D01；国务院调休安排 | M15: 按调休上课日完成 110 分钟；不补成周末大课 | N15: 未开始
A16: 46286 | B16: 3 | C16: 周一 | D16: 基础期 | E16: 工作日 | F16: 105 | G16: [25min] 不背单词·六级词书：新词 40（周末 50）+ 到期复习；20–25 分钟到点即停 | H16: [40min] D02 长对话 1 组：限时作答→精听 2 轮→听写 6 个转折/问题句 | I16: [30min] D02 仔细阅读 1 篇：10 分钟做题 + 20 分钟逐题定位证据 | K16: [10min] 错题写 1 条根因 + 1 条下次动作 | L16: D02；不背单词；每日英语听力/随书音频 | M16: 能指出每道错题的原文证据；精听句可脱稿复述大意 | N16: 未开始
A17: 46287 | B17: 3 | C17: 周二 | D17: 基础期 | E17: 工作日 | F17: 110 | G17: [25min] 不背单词·六级词书：新词 40（周末 50）+ 到期复习；20–25 分钟到点即停 | H17: [30min] D02 篇章听力 1 组：先盲听作答，再逐句回放难句 | I17: [35min] D02 长篇匹配：15 分钟限时 + 20 分钟整理同义替换 | J17: [20min] 真题翻译 3–4 句：先独立写，再对照范文只改语法和搭配 | L17: D02；真题范文 | M17: 记录至少 5 组同义替换；翻译改出 3 处可复用表达 | N17: 未开始
A18: 46288 | B18: 3 | C18: 周三 | D18: 基础期 | E18: 工作日 | F18: 110 | G18: [25min] 不背单词·六级词书：新词 40（周末 50）+ 到期复习；20–25 分钟到点即停 | H18: [45min] D02 讲座/讲话 1 组：画结构（主题→分点→例子）并跟读 8 句 | I18: [30min] D02 仔细阅读 1 篇：训练讲座讲话 + 推断题，每题标定位词 | J18: [10min] 写作：只列 3 段提纲 + 每段 1 个主题句 | L18: D02；随书听力文本 | M18: 能用中文复述讲座三层结构；提纲 10 分钟内完成 | N18: 未开始
A19: 46289 | B19: 3 | C19: 周四 | D19: 基础期 | E19: 工作日 | F19: 115 | G19: [25min] 不背单词·六级词书：新词 40（周末 50）+ 到期复习；20–25 分钟到点即停 | H19: [35min] D02 讲座/讲话第 2 组：限时 + 错句精听 + 隔句跟读 | I19: [40min] D02 仔细阅读第 2 篇：12 分钟做题 + 28 分钟错项排除 | J19: [15min] 翻译：复写本周 5 个高频句型，换主题词各造 1 句 | L19: D02；错题记录 | M19: 讲座错题二次作答全对；阅读能解释 4 个干扰项为何错 | N19: 未开始
A20: 46290 | B20: 3 | C20: 周五 | D20: 基础期 | E20: 中秋·轻量 | F20: 35 | G20: [20min] 到期词 + 本周错词；不加新词 | H20: [15min] D02 精听句盲听一遍，能复述大意即可 | L20: 不背单词；D02 音频 | M20: 35 分钟到点结束；不安排补课 | N20: 未开始
A21: 46291 | B21: 3 | C21: 周六 | D21: 基础期 | E21: 中秋假期·弹性 | F21: 125 | G21: [20min] 新词 30 + 到期复习 | H21: [45min] D02 听力整套限时 + 只改最有代表性的 5 题 | I21: [35min] D02 仔细阅读 2 篇，计时并标证据 | J21: [15min] 翻译错句改写 3 句 | K21: [10min] 未完成可直接跳过，不顺延 | L21: D02；计时器 | M21: 完成核心听读即可；总时长不超过 125 分钟 | N21: 未开始
A22: 46292 | B22: 3 | C22: 周日 | D22: 基础期 | E22: 中秋假期·弹性 | F22: 145 | G22: [20min] 到期词 + 本周错词 | H22: [35min] D02 听力错题二测 | I22: [40min] D02 阅读错题二测 + 5 组同义替换 | J22: [30min] 完整作文 1 篇，按 30 分钟完成 | K22: [20min] 周复盘 + 旅行前任务封箱 | L22: D02；每周复盘 | M22: 本周结清，不把任务带入旅行 | N22: 未开始
A23: 46293 | B23: 4 | C23: 周一 | D23: 基础期 | E23: 工作日 | F23: 105 | G23: [25min] 不背单词·六级词书：新词 40（周末 50）+ 到期复习；20–25 分钟到点即停 | H23: [40min] D03 长对话 1 组：限时作答→精听 2 轮→听写 6 个转折/问题句 | I23: [30min] D03 仔细阅读 1 篇：10 分钟做题 + 20 分钟逐题定位证据 | K23: [10min] 错题写 1 条根因 + 1 条下次动作 | L23: D03；不背单词；每日英语听力/随书音频 | M23: 能指出每道错题的原文证据；精听句可脱稿复述大意 | N23: 未开始
A24: 46294 | B24: 4 | C24: 周二 | D24: 基础期 | E24: 工作日 | F24: 110 | G24: [25min] 不背单词·六级词书：新词 40（周末 50）+ 到期复习；20–25 分钟到点即停 | H24: [30min] D03 篇章听力 1 组：先盲听作答，再逐句回放难句 | I24: [35min] D03 长篇匹配：15 分钟限时 + 20 分钟整理同义替换 | J24: [20min] 真题翻译 3–4 句：先独立写，再对照范文只改语法和搭配 | L24: D03；真题范文 | M24: 记录至少 5 组同义替换；翻译改出 3 处可复用表达 | N24: 未开始
A25: 46295 | B25: 4 | C25: 周三 | D25: 基础期 | E25: 旅行·仅词汇 | F25: 20 | G25: [20min] 只做 App 到期词；不加新词，不补任何听读 | L25: 不背单词 | M25: 20 分钟到点停止 | N25: 未开始
A26: 46296 | B26: 4 | C26: 周四 | D26: 基础期 | E26: 旅行·仅词汇 | F26: 15 | G26: [15min] 只复习 App 到期词；若行程紧可直接跳过且不补 | L26: 不背单词 | M26: 最多 15 分钟；不形成欠账 | N26: 未开始
A27: 46297 | B27: 4 | C27: 周五 | D27: 基础期 | E27: 旅行·完全留空 | F27: 0 | L27: 无 | M27: 无需学习，也无需补做；返回后从 10/6 直接继续 | N27: 计划休息
A28: 46298 | B28: 4 | C28: 周六 | D28: 基础期 | E28: 旅行·完全留空 | F28: 0 | L28: 无 | M28: 无需学习，也无需补做；返回后从 10/6 直接继续 | N28: 计划休息
A29: 46299 | B29: 4 | C29: 周日 | D29: 基础期 | E29: 旅行·完全留空 | F29: 0 | L29: 无 | M29: 无需学习，也无需补做；返回后从 10/6 直接继续 | N29: 计划休息
A30: 46300 | B30: 5 | C30: 周一 | D30: 基础期 | E30: 旅行·完全留空 | F30: 0 | L30: 无 | M30: 无需学习，也无需补做；返回后从 10/6 直接继续 | N30: 计划休息
A31: 46301 | B31: 5 | C31: 周二 | D31: 基础期 | E31: 旅行后恢复 | F31: 80 | G31: [20min] 到期词复习；只加 20 个新词 | H31: [30min] D03 选 1 组长对话：限时 + 只精听 4 个难句 | I31: [25min] D03 仔细阅读 1 篇：12 分钟做题 + 13 分钟定位 | K31: [5min] 写下旅行后第一阻力，不补旧任务 | L31: D03；不背单词 | M31: 完成 80 分钟即恢复成功；不追赶 | N31: 未开始
A32: 46302 | B32: 5 | C32: 周三 | D32: 基础期 | E32: 旅行后恢复 | F32: 100 | G32: [20min] 新词 25 + 到期复习 | H32: [35min] D03 篇章听力 1 组：限时 + 6 句跟读 | I32: [30min] D03 长篇匹配 1 篇：15 分钟作答 + 15 分钟同义替换 | J32: [10min] 作文列 3 段提纲 | K32: [5min] 确认 10/8 恢复正常 | L32: D03；随书音频 | M32: 听读各完成一项；不超过 100 分钟 | N32: 未开始
A33: 46303 | B33: 5 | C33: 周四 | D33: 基础期 | E33: 工作日 | F33: 115 | G33: [25min] 不背单词·六级词书：新词 40（周末 50）+ 到期复习；20–25 分钟到点即停 | H33: [35min] D03 讲座/讲话第 2 组：限时 + 错句精听 + 隔句跟读 | I33: [40min] D03 仔细阅读第 2 篇：12 分钟做题 + 28 分钟错项排除 | J33: [15min] 翻译：复写本周 5 个高频句型，换主题词各造 1 句 | L33: D03；错题记录 | M33: 讲座错题二次作答全对；阅读能解释 4 个干扰项为何错 | N33: 未开始
A34: 46304 | B34: 5 | C34: 周五 | D34: 基础期 | E34: 工作日 | F34: 100 | G34: [20min] 本周词汇到期复习，不加量 | H34: [25min] 本周精听句盲听复测：不看文本写关键词，错句回放 1 次 | I34: [30min] D03 选词填空 1 篇：12 分钟限时；只总结词性和固定搭配 | J34: [20min] 写作：把周三提纲扩写为开头 + 结尾，各 3–4 句 | K34: [5min] 标记周末优先复习的 3 个错误 | L34: D03；本周错题 | M34: 精听复测正确率≥80%；形成 1 个可复用开头和结尾 | N34: 未开始
A35: 46305 | B35: 5 | C35: 周六 | D35: 基础期 | E35: 调休上课日 | F35: 105 | G35: [20min] 到期词 + 错词，不加量 | H35: [35min] D03 听力整套后只精改错题所在段 | I35: [30min] D03 仔细阅读 1 篇 + 证据定位 | J35: [10min] 翻译错句 3 句 | K35: [10min] 记录正确率 | L35: D03；国务院调休安排 | M35: 按工作日完成；不因周六排 3 小时 | N35: 未开始
A36: 46306 | B36: 5 | C36: 周日 | D36: 基础期 | E36: 周末 | F36: 170 | G36: [25min] 到期词复习 + 本周错词 30 个 | H36: [40min] 本周听力错句二测：盲听→口头复述→对照文本 | I36: [45min] 本周阅读错题二测 + 同题型新题 1 篇 | J36: [40min] 写作/翻译交替：奇数周完整作文，偶数周完整翻译；用范文或 AI 只做批改 | K36: [20min] 填写每周复盘：完成率、听/读正确率、下周只改 1 件事 | L36: D03；每周复盘；AI/范文 | M36: 二测不看答案；完成周复盘并写出下周唯一优先项 | N36: 未开始
A37: 46307 | B37: 6 | C37: 周一 | D37: 强化期 | E37: 工作日 | F37: 110 | G37: [20min] 新词 30–35 + 到期复习；把真题错词加入自定义词库 | H37: [40min] D04 听力 25 题：30 分钟限时 + 10 分钟只标错因 | I37: [35min] D04 仔细阅读 1 篇 + 长篇匹配半篇，严格计时 | K37: [15min] 挑 2 道最典型错题写证据链 | L37: D04；计时器 | M37: 听力不停顿；阅读每题都有定位词；完成 2 条证据链 | N37: 未开始
A38: 46308 | B38: 6 | C38: 周二 | D38: 强化期 | E38: 工作日 | F38: 115 | G38: [20min] 新词 30–35 + 到期复习；把真题错词加入自定义词库 | H38: [35min] 昨日听力错题精听：只处理错题所在段，听写 8 个关键句 | I38: [35min] D04 长篇匹配 1 篇：12–15 分钟 + 同义替换表 | J38: [25min] 翻译 1 段：25 分钟完成；只检查时态、单复数、主谓一致 | L38: D04；错题记录 | M38: 8 个关键句至少 6 句听写正确；翻译无低级语法错 | N38: 未开始
A39: 46309 | B39: 6 | C39: 周三 | D39: 强化期 | E39: 工作日 | F39: 120 | G39: [20min] 新词 30–35 + 到期复习；把真题错词加入自定义词库 | H39: [40min] D04 讲座/讲话 1 组：记录路标词与层次，复述 60 秒 | I39: [45min] D04 仔细阅读 2 篇：22 分钟作答 + 23 分钟订正 | J39: [15min] 写作：15 分钟完成审题、立场、两条理由和例子 | L39: D04；录音机 | M39: 讲座题≥6/10（不足则记录错因）；两篇阅读总作答≤22 分钟 | N39: 未开始
A40: 46310 | B40: 6 | C40: 周四 | D40: 强化期 | E40: 工作日 | F40: 120 | G40: [20min] 新词 30–35 + 到期复习；把真题错词加入自定义词库 | H40: [25min] 隔日盲听复测：周一错题 + 周三讲座，仍错的进入红色清单 | I40: [75min] D04 阅读 30 题：40 分钟整套 + 35 分钟精改仔细阅读 | L40: D04；红色错题清单 | M40: 阅读全套≤40 分钟；仔细阅读正确≥6/10 | N40: 未开始
...

Sheet 资料清单
A1: 资料清单：少买、用透
A2: 核心原则：只买一套真题；电子工具各司其职，不同时开多个同类 App。价格为大致区间，以购买时为准。
A4: 类别 | B4: 资料/工具 | C4: 优先级 | D4: 预计费用 | E4: 怎么用 | F4: 频率 | G4: 替代/备注 | H4: 链接
A5: 纸质·核心 | B5: 最新六级真题详解（首选星火；新东方同类最新版也可，二选一） | C5: 必备 | D5: 约 35–60 元 | E5: 购买时确认：至少 12 套完整真题、原版音频、听力原文、逐题解析；按 F0/D01–D05/M01–M06 编号 | F5: 全程 | G5: 不要同时买两套；书名随版本略变，以功能为准
A6: 纸质·可选 | B6: 新东方六级词汇乱序版/同类高频词汇书 | C6: 可选 | D6: 约 30–45 元 | E6: 只在不喜欢 App 时使用；每天按时间上限背，不追页码 | F6: 每日 20–25min | G6: 已用 App 就不买
A7: 电子·词汇 | B7: 不背单词（六级词书） | C7: 必备 | D7: 基础功能可免费 | E7: 前期新词 35–40 + 到期复习；后期停新词，只复习真题错词 | F7: 每日 | G7: 墨墨/百词斩可替代，但只能选一个 | H7: https://www.bbdc.cn/
A8: 电子·真题音频 | B8: 所购真题册随书音频/小程序 | C8: 必备 | D8: 随书 | E8: 始终以真题原音为主；下载离线，按句回放 | F8: 每周 5–6 次 | G8: 音频必须与试卷版本对应
A9: 电子·精听 | B9: 每日英语听力 | C9: 推荐 | D9: 基础功能可免费 | E9: 导入/搜索真题音频，使用句子回放、变速和文本对照；不做整篇逐字听写 | F9: 每周 4–5 次 | G9: 随书播放器若能逐句回放也够用 | H9: https://dict.eudic.net/ting
A10: 电子·写译批改 | B10: 当前使用的 ChatGPT/Codex 或学校批改网 | C10: 推荐 | D10: 已有服务/校内资源 | E10: 先独立限时写，再要求按 CET-6 维度指出 3–5 个问题并给改写理由；禁止直接代写 | F10: 每周 1–2 次 | G10: 真题范文自查也可
A11: 电子·错题 | B11: 本工作簿：错题记录 + 模考记录 | C11: 必备 | D11: 免费 | E11: 只记高价值错题：错因、证据、下次动作、48 小时/7 天复测 | F11: 每次训练后 | G11: 不另装笔记 App，减少切换
A12: 电子·补充听力 | B12: BBC Learning English · 6 Minute English | C12: 可选 | D12: 免费 | E12: 只作旅行/轻量日补充；真题完成后再听，不替代真题 | F12: 每周≤1 次 | G12: 听懂主旨即可，不逐字查词 | H12: https://www.bbc.co.uk/learningenglish/english/features/6-minute-english
A13: 官方信息 | B13: 全国大学英语四六级考试官网/报名网 | C13: 必备 | D13: 免费 | E13: 核对报名、考试日期、准考证与成绩；9 月起每周检查一次学校通知即可 | F13: 每周 1 次 | G13: 不要以培训机构日历代替官方公告 | H13: https://cet.neea.edu.cn/html1/category/16093/1124-1.htm
A14: 硬件 | B14: 现有耳机/收音设备 + 计时器 | C14: 必备 | D14: 0 元（已有） | E14: 精听、模考使用同一设备；提前确认学校听力接收方式 | F14: 全程 | G14: 考试用品以莆田学院通知为准
A17: 推荐购买结论
A18: 性价比方案：纸质只买 1 套最新版六级真题（约 35–60 元）。词汇用不背单词，精听用随书音频 + 每日英语听力，写译用真题范文或现有 AI 做纠错，本工作簿直接承担错题与模考记录。若确实偏爱纸质背词，再加 1 本词汇书；不建议购买阅读、听力、作文三本专项书。

Sheet 真题映射
A1: 真题编号与使用顺序
A2: 先按用途编号，再把所购版本的实际年份/套次填入。M01–M06 在指定日期前不得看答案。
A4: 编号 | B4: 用途 | C4: 建议选卷 | D4: 实际年份/套次（购买后填） | E4: 是否看过答案 | F4: 计划日期 | G4: 完成日期 | H4: 估分/正确率 | I4: 备注
A5: F0 | B5: 完整基线 | C5: 最旧且完整的一套 | E5: 否 | F5: 46277 | I5: 一次完成，保留真实基线
A6: D01 | B6: 拆分专项 | C6: 从旧到新第 2 套 | E6: 可拆 | F6: 按每日计划 | I6: 可分听力/阅读/写译训练
A7: D02 | B7: 拆分专项 | C7: 从旧到新第 3 套 | E7: 可拆 | F7: 按每日计划 | I7: 可分听力/阅读/写译训练
A8: D03 | B8: 拆分专项 | C8: 从旧到新第 4 套 | E8: 可拆 | F8: 按每日计划 | I8: 可分听力/阅读/写译训练
A9: D04 | B9: 拆分专项 | C9: 从旧到新第 5 套 | E9: 可拆 | F9: 按每日计划 | I9: 可分听力/阅读/写译训练
A10: D05 | B10: 拆分专项 | C10: 从旧到新第 6 套 | E10: 可拆 | F10: 按每日计划 | I10: 可分听力/阅读/写译训练
A11: M01 | B11: 全真模考 | C11: 最新六套中从旧到新第 1 套 | E11: 否 | F11: 46326 | I11: 指定日期前不翻答案/听力原文
A12: M02 | B12: 全真模考 | C12: 最新六套中从旧到新第 2 套 | E12: 否 | F12: 46333 | I12: 指定日期前不翻答案/听力原文
A13: M03 | B13: 全真模考 | C13: 最新六套中从旧到新第 3 套 | E13: 否 | F13: 46341 | I13: 指定日期前不翻答案/听力原文
A14: M04 | B14: 全真模考 | C14: 最新六套中从旧到新第 4 套 | E14: 否 | F14: 46347 | I14: 指定日期前不翻答案/听力原文
A15: M05 | B15: 全真模考 | C15: 最新六套中从旧到新第 5 套 | E15: 否 | F15: 46354 | I15: 指定日期前不翻答案/听力原文
A16: M06 | B16: 全真模考 | C16: 最新六套中从旧到新第 6 套 | E16: 否 | F16: 46361 | I16: 指定日期前不翻答案/听力原文

Sheet 每周复盘
A1: 每周复盘
A2: 每周日用 15–20 分钟填写。完成率低不等于失败：只找一个最值得调整的变量。
A4: 周次 | B4: 开始 | C4: 结束 | D4: 本周主题 | E4: 计划(min) | F4: 实际(min) | G4: 计划天数 | H4: 完成天数 | I4: 完成率 | J4: 听力正确/25 | K4: 阅读正确/30 | L4: 模考估分 | M4: 最大问题 | N4: 下周唯一调整 | O4: 状态
A5: 1 | B5: 46272 | C5: 46278 | D5: 诊断启动 | E5: =SUMIFS('每日计划'!$F:$F,'每日计划'!$A:$A,">="&B5,'每日计划'!$A:$A,"<="&C5) | F5: =SUMIFS('每日计划'!$O:$O,'每日计划'!$A:$A,">="&B5,'每日计划'!$A:$A,"<="&C5) | G5: =COUNTIFS('每日计划'!$A:$A,">="&B5,'每日计划'!$A:$A,"<="&C5,'每日计划'!$F:$F,">0") | H5: =COUNTIFS('每日计划'!$A:$A,">="&B5,'每日计划'!$A:$A,"<="&C5,'每日计划'!$N:$N,"已完成") | I5: =IFERROR(H5/G5,0) | O5: 未复盘
A6: 2 | B6: 46279 | C6: 46285 | D6: 基础Ⅰ：长对话 + 仔细阅读 | E6: =SUMIFS('每日计划'!$F:$F,'每日计划'!$A:$A,">="&B6,'每日计划'!$A:$A,"<="&C6) | F6: =SUMIFS('每日计划'!$O:$O,'每日计划'!$A:$A,">="&B6,'每日计划'!$A:$A,"<="&C6) | G6: =COUNTIFS('每日计划'!$A:$A,">="&B6,'每日计划'!$A:$A,"<="&C6,'每日计划'!$F:$F,">0") | H6: =COUNTIFS('每日计划'!$A:$A,">="&B6,'每日计划'!$A:$A,"<="&C6,'每日计划'!$N:$N,"已完成") | I6: =IFERROR(H6/G6,0) | O6: 未复盘
A7: 3 | B7: 46286 | C7: 46292 | D7: 基础Ⅱ：讲座讲话 + 推断题 | E7: =SUMIFS('每日计划'!$F:$F,'每日计划'!$A:$A,">="&B7,'每日计划'!$A:$A,"<="&C7) | F7: =SUMIFS('每日计划'!$O:$O,'每日计划'!$A:$A,">="&B7,'每日计划'!$A:$A,"<="&C7) | G7: =COUNTIFS('每日计划'!$A:$A,">="&B7,'每日计划'!$A:$A,"<="&C7,'每日计划'!$F:$F,">0") | H7: =COUNTIFS('每日计划'!$A:$A,">="&B7,'每日计划'!$A:$A,"<="&C7,'每日计划'!$N:$N,"已完成") | I7: =IFERROR(H7/G7,0) | O7: 未复盘
A8: 4 | B8: 46293 | C8: 46299 | D8: 中秋复盘 + 旅行缓冲 | E8: =SUMIFS('每日计划'!$F:$F,'每日计划'!$A:$A,">="&B8,'每日计划'!$A:$A,"<="&C8) | F8: =SUMIFS('每日计划'!$O:$O,'每日计划'!$A:$A,">="&B8,'每日计划'!$A:$A,"<="&C8) | G8: =COUNTIFS('每日计划'!$A:$A,">="&B8,'每日计划'!$A:$A,"<="&C8,'每日计划'!$F:$F,">0") | H8: =COUNTIFS('每日计划'!$A:$A,">="&B8,'每日计划'!$A:$A,"<="&C8,'每日计划'!$N:$N,"已完成") | I8: =IFERROR(H8/G8,0) | O8: 未复盘
A9: 5 | B9: 46300 | C9: 46306 | D9: 旅行后重启：篇章听力 + 长篇匹配 | E9: =SUMIFS('每日计划'!$F:$F,'每日计划'!$A:$A,">="&B9,'每日计划'!$A:$A,"<="&C9) | F9: =SUMIFS('每日计划'!$O:$O,'每日计划'!$A:$A,">="&B9,'每日计划'!$A:$A,"<="&C9) | G9: =COUNTIFS('每日计划'!$A:$A,">="&B9,'每日计划'!$A:$A,"<="&C9,'每日计划'!$F:$F,">0") | H9: =COUNTIFS('每日计划'!$A:$A,">="&B9,'每日计划'!$A:$A,"<="&C9,'每日计划'!$N:$N,"已完成") | I9: =IFERROR(H9/G9,0) | O9: 未复盘
A10: 6 | B10: 46307 | C10: 46313 | D10: 强化Ⅰ：整套听力控时 | E10: =SUMIFS('每日计划'!$F:$F,'每日计划'!$A:$A,">="&B10,'每日计划'!$A:$A,"<="&C10) | F10: =SUMIFS('每日计划'!$O:$O,'每日计划'!$A:$A,">="&B10,'每日计划'!$A:$A,"<="&C10) | G10: =COUNTIFS('每日计划'!$A:$A,">="&B10,'每日计划'!$A:$A,"<="&C10,'每日计划'!$F:$F,">0") | H10: =COUNTIFS('每日计划'!$A:$A,">="&B10,'每日计划'!$A:$A,"<="&C10,'每日计划'!$N:$N,"已完成") | I10: =IFERROR(H10/G10,0) | O10: 未复盘
A11: 7 | B11: 46314 | C11: 46320 | D11: 强化Ⅱ：高权重讲座 + 阅读控时 | E11: =SUMIFS('每日计划'!$F:$F,'每日计划'!$A:$A,">="&B11,'每日计划'!$A:$A,"<="&C11) | F11: =SUMIFS('每日计划'!$O:$O,'每日计划'!$A:$A,">="&B11,'每日计划'!$A:$A,"<="&C11) | G11: =COUNTIFS('每日计划'!$A:$A,">="&B11,'每日计划'!$A:$A,"<="&C11,'每日计划'!$F:$F,">0") | H11: =COUNTIFS('每日计划'!$A:$A,">="&B11,'每日计划'!$A:$A,"<="&C11,'每日计划'!$N:$N,"已完成") | I11: =IFERROR(H11/G11,0) | O11: 未复盘
A12: 8 | B12: 46321 | C12: 46327 | D12: 强化Ⅲ：四项串联 + 首次全真 | E12: =SUMIFS('每日计划'!$F:$F,'每日计划'!$A:$A,">="&B12,'每日计划'!$A:$A,"<="&C12) | F12: =SUMIFS('每日计划'!$O:$O,'每日计划'!$A:$A,">="&B12,'每日计划'!$A:$A,"<="&C12) | G12: =COUNTIFS('每日计划'!$A:$A,">="&B12,'每日计划'!$A:$A,"<="&C12,'每日计划'!$F:$F,">0") | H12: =COUNTIFS('每日计划'!$A:$A,">="&B12,'每日计划'!$A:$A,"<="&C12,'每日计划'!$N:$N,"已完成") | I12: =IFERROR(H12/G12,0) | O12: 未复盘
A13: 9 | B13: 46328 | C13: 46334 | D13: 模考Ⅰ：M01 修复 + M02 | E13: =SUMIFS('每日计划'!$F:$F,'每日计划'!$A:$A,">="&B13,'每日计划'!$A:$A,"<="&C13) | F13: =SUMIFS('每日计划'!$O:$O,'每日计划'!$A:$A,">="&B13,'每日计划'!$A:$A,"<="&C13) | G13: =COUNTIFS('每日计划'!$A:$A,">="&B13,'每日计划'!$A:$A,"<="&C13,'每日计划'!$F:$F,">0") | H13: =COUNTIFS('每日计划'!$A:$A,">="&B13,'每日计划'!$A:$A,"<="&C13,'每日计划'!$N:$N,"已完成") | I13: =IFERROR(H13/G13,0) | O13: 未复盘
A14: 10 | B14: 46335 | C14: 46341 | D14: 模考Ⅱ：运动会减量 + M03 | E14: =SUMIFS('每日计划'!$F:$F,'每日计划'!$A:$A,">="&B14,'每日计划'!$A:$A,"<="&C14) | F14: =SUMIFS('每日计划'!$O:$O,'每日计划'!$A:$A,">="&B14,'每日计划'!$A:$A,"<="&C14) | G14: =COUNTIFS('每日计划'!$A:$A,">="&B14,'每日计划'!$A:$A,"<="&C14,'每日计划'!$F:$F,">0") | H14: =COUNTIFS('每日计划'!$A:$A,">="&B14,'每日计划'!$A:$A,"<="&C14,'每日计划'!$N:$N,"已完成") | I14: =IFERROR(H14/G14,0) | O14: 未复盘
A15: 11 | B15: 46342 | C15: 46348 | D15: 模考Ⅲ：M03 修复 + M04 | E15: =SUMIFS('每日计划'!$F:$F,'每日计划'!$A:$A,">="&B15,'每日计划'!$A:$A,"<="&C15) | F15: =SUMIFS('每日计划'!$O:$O,'每日计划'!$A:$A,">="&B15,'每日计划'!$A:$A,"<="&C15) | G15: =COUNTIFS('每日计划'!$A:$A,">="&B15,'每日计划'!$A:$A,"<="&C15,'每日计划'!$F:$F,">0") | H15: =COUNTIFS('每日计划'!$A:$A,">="&B15,'每日计划'!$A:$A,"<="&C15,'每日计划'!$N:$N,"已完成") | I15: =IFERROR(H15/G15,0) | O15: 未复盘
A16: 12 | B16: 46349 | C16: 46355 | D16: 模考Ⅳ：稳定 425 + M05 | E16: =SUMIFS('每日计划'!$F:$F,'每日计划'!$A:$A,">="&B16,'每日计划'!$A:$A,"<="&C16) | F16: =SUMIFS('每日计划'!$O:$O,'每日计划'!$A:$A,">="&B16,'每日计划'!$A:$A,"<="&C16) | G16: =COUNTIFS('每日计划'!$A:$A,">="&B16,'每日计划'!$A:$A,"<="&C16,'每日计划'!$F:$F,">0") | H16: =COUNTIFS('每日计划'!$A:$A,">="&B16,'每日计划'!$A:$A,"<="&C16,'每日计划'!$N:$N,"已完成") | I16: =IFERROR(H16/G16,0) | O16: 未复盘
... A18: 14 | B18: 46363 | C18: 46368 | D18: 冲刺Ⅱ：封口与减量 | E18: =SUMIFS('每日计划'!$F:$F,'每日计划'!$A:$A,">="&B18,'每日计划'!$A:$A,"<="&C18) | F18: =SUMIFS('每日计划'!$O:$O,'每日计划'!$A:$A,">="&B18,'每日计划'!$A:$A,"<="&C18) | G18: =COUNTIFS('每日计划'!$A:$A,">="&B18,'每日计划'!$A:$A,"<="&C18,'每日计划'!$F:$F,">0") | H18: =COUNTIFS('每日计划'!$A:$A,">="&B18,'每日计划'!$A:$A,"<="&C18,'每日计划'!$N:$N,"已完成") | I18: =IFERROR(H18/G18,0) | O18: 未复盘

Sheet 模考记录
A1: 模考记录
A2: 原始正确数与出版社估分都只看趋势。CET 采用常模转换，不做“每题固定多少分”的简单换算。
A4: 日期 | B4: 试卷 | C4: 性质 | D4: 写作自评/15 | E4: 听力正确/25 | F4: 阅读正确/30 | G4: 翻译自评/15 | H4: 出版社估分 | I4: 用时(min) | J4: 是否中断 | K4: 最大失分点 | L4: 48h复测日期 | M4: 阶段目标 | N4: 备注
A5: 46277 | B5: F0 | C5: 基线 | J5: 否 | L5: 46279 | M5: 记录真实基线
A6: 46326 | B6: M01 | C6: 全真 | J6: 否 | L6: 46328 | M6: ≥380
A7: 46333 | B7: M02 | C7: 全真 | J7: 否 | L7: 46335 | M7: ≈400
A8: 46341 | B8: M03 | C8: 全真 | J8: 否 | L8: 46343 | M8: ≥415
A9: 46347 | B9: M04 | C9: 全真 | J9: 否 | L9: 46349 | M9: ≥425
A10: 46354 | B10: M05 | C10: 全真 | J10: 否 | L10: 46356 | M10: ≥435
A11: 46361 | B11: M06 | C11: 全真 | J11: 否 | L11: 46363 | M11: ≥450，或近两套均≥425

Sheet 错题记录
A1: 错题记录
A2: 只记会重复犯、值得复测的题。每条必须写“根因 + 下次动作”，不要抄长解析。
A4: 编号 | B4: 日期 | C4: 来源 | D4: 模块 | E4: 题型 | F4: 我的答案 | G4: 正确答案 | H4: 根因 | I4: 证据/关键句 | J4: 下次动作 | K4: 48h复测 | L4: 7天复测 | M4: 掌握状态 | N4: 备注
A5: =IF(B5="","",ROW()-4)
A6: =IF(B6="","",ROW()-4)
A7: =IF(B7="","",ROW()-4)
A8: =IF(B8="","",ROW()-4)
A9: =IF(B9="","",ROW()-4)
A10: =IF(B10="","",ROW()-4)
A11: =IF(B11="","",ROW()-4)
A12: =IF(B12="","",ROW()-4)
A13: =IF(B13="","",ROW()-4)
A14: =IF(B14="","",ROW()-4)
A15: =IF(B15="","",ROW()-4)
A16: =IF(B16="","",ROW()-4)
... A104: =IF(B104="","",ROW()-4)

Sheet 使用说明
A1: 怎么用这份计划
A2: 建议先看 5 分钟，再从“每日计划”开始。所有浅黄色单元格都表示需要确认或弹性处理。
A4: 每天
A5: • 打开“每日计划”，只看当天一行；完成后把状态改为“已完成”，填写实际分钟和 1–5 分自评。
A6: • 任务中的分钟数是时间上限。到点停止比为了做完题拖到深夜更重要。
A7: • 当天漏做：不整体顺延。只带走最重要的一项，放到周日复盘；最多 1 项。
A10: 每周
A11: • 周日填写“每周复盘”：完成率、听力/阅读原始正确数、最大问题、下周唯一调整。
A12: • 完成率低于 70%：下周总量降 15%，但保留听力和仔细阅读；高于 85% 才考虑加量。
A13: • 模考后的 48 小时内完成错题二测；7 天后只复测仍然不稳的题。
A16: 真题
A17: • 购买后先去“真题映射”填实际年份/套次。F0 是基线，D01–D05 可拆，M01–M06 为保留模考卷。
... A34: 来源与核实日期
A35: 来源 | B35: 链接/出处 | C35: 本计划如何使用
A36: 教育部教育考试院 CET 考试动态 | B36: https://cet.neea.edu.cn/html1/category/16093/1124-1.htm | C36: 截至 2026-08-27 未见 2026 下半年正式报名公告
A37: CET 报名网考试时间 | B37: https://cet-kw.neea.edu.cn/Home/TestDatePlan.html | C37: 截至 2026-08-27 仍只列 2026 上半年安排
A38: CET 笔试介绍 | B38: https://cet.neea.edu.cn/xhtml1/folder/16113/1586-1.htm | C38: 官方说明笔试每年 6 月、12 月举行
A39: 2026 上半年官方公告 | B39: https://cet.neea.edu.cn/html1/report/2603/2-1.htm | C39: 用于参考近次 CET-6 时段 15:00–17:25；下半年仍待确认
A40: 国务院 2026 年节假日通知 | B40: https://www.gov.cn/zhengce/zhengceku/202511/content_7047091.htm | C40: 中秋 9/25–27；国庆 10/1–7，9/20、10/10 调休上班
A41: 上海市年度考试计划 | B41: https://edu.sh.gov.cn/cmsres/28/286d084bda7e46cea1e7d4702b480c86/19d146e3093dac64c68581d795a298e2.pdf | C41: 提供 12/12 排程依据，但不是本次中央正式公告，可能调整
A42: 莆田学院 2026–2027 第一学期校历 | B42: 用户提供图片 | C42: 9/7 开学；9/25 中秋；11/12–14 运动会
